from odoo import models, fields, api, _
from odoo.exceptions import UserError, ValidationError

class SaleOrder(models.Model):
    _inherit = 'sale.order'

    price_promo = fields.Float(string='Price Promo')

    @api.multi
    def action_cancel(self):
        super(SaleOrder, self).action_cancel()
        self.write({'price_promo': 0})

class SaleOrderLine(models.Model):
    _inherit = 'sale.order.line'

    @api.depends('product_uom_qty', 'discount', 'price_unit', 'tax_id', 'order_id.price_promo')
    def _compute_amount(self):
        for line in self:
            price = (line.price_unit - line.order_id.price_promo)  * (1 - (line.discount or 0.0) / 100.0)
            taxes = line.tax_id.compute_all(price, line.order_id.currency_id, line.product_uom_qty, product=line.product_id, partner=line.order_id.partner_shipping_id)
            line.update({
                'price_tax': sum(t.get('amount', 0.0) for t in taxes.get('taxes', [])),
                'price_total': taxes['total_included'],
                'price_subtotal': taxes['total_excluded'],
            })
